Workbook
Name _SP1: [1]FES!#REF!
Name _SP10: [1]FES!#REF!
Name _SP11: [1]FES!#REF!
Name _SP12: [1]FES!#REF!
Name _SP13: [1]FES!#REF!
Name _SP14: [1]FES!#REF!
Name _SP15: [1]FES!#REF!
Name _SP16: [1]FES!#REF!
Name _SP17: [1]FES!#REF!
Name _SP18: [1]FES!#REF!
Name _SP19: [1]FES!#REF!
Name _SP2: [1]FES!#REF!
Name _SP20: [1]FES!#REF!
Name _SP3: [1]FES!#REF!
Name _SP4: [1]FES!#REF!
Name _SP5: [1]FES!#REF!
Name _SP7: [1]FES!#REF!
Name _SP8: [1]FES!#REF!
Name _SP9: [1]FES!#REF!
Name a: #NAME?
Name B: #NAME?
Name CompOt: #NAME?
Name CompOt2: #NAME?
Name CompRas: #NAME?
Name Contents: [2]Содержание!$A$3
Name CUR_VER: [3]Заголовок!$B$21
Name e: #NAME?
Name ew: #NAME?
Name Excel_BuiltIn__FilterDatabase_19: #NAME?
Name Excel_BuiltIn__FilterDatabase_22: #NAME?
Name Excel_BuiltIn__FilterDatabase_8_1: "$#ССЫЛ!.$D$1:$D$100"
Name Excel_BuiltIn__FilterDatabase_8_21: #REF!
Name Excel_BuiltIn_Print_Area_15: (#REF!,#REF!)
Name Excel_BuiltIn_Print_Area_16: (#REF!,#REF!)
Name Excel_BuiltIn_Print_Titles_15: #REF!
Name Excel_BuiltIn_Print_Titles_16: #REF!
Name EXPE: #REF!
Name EXPF: #REF!
Name EXPM: #REF!
Name fg: #NAME?
Name fil_2_16: #N/A
Name fil_2_18: #N/A
Name fil_2_19: #N/A
Name fil_2_22: #NAME?
Name fil_21: #REF!
Name fil_3_16: #N/A
Name fil_3_18: #N/A
Name fil_3_19: #N/A
Name fil_3_22: #NAME?
Name fil_4_16: #N/A
Name fil_4_18: #N/A
Name fil_4_19: #N/A
Name fil_4_22: #NAME?
Name g: #NAME?
Name H?Address: [2]Заголовок!$B$7:$G$7
Name H?Description: [2]Заголовок!$A$4
Name H?EntityName: [2]Заголовок!$B$6:$G$6
Name H?Name: [2]Заголовок!$G$1
Name H?OKATO: [2]Заголовок!$D$12
Name H?OKFS: [2]Заголовок!$G$12

Sheet План ОПЭ
B1: Общество | C1: Филиал | D1: РЭС | E1: Абоненский номер | F1: IMEI | G1: Наличие ПО на МУ | H1: ФИО начальника РЭС | I1: Номер телефона | J1: ФИО ГИ РЭС | K1: Номер телефона
A2: 1 | B2: Центр | C2: Белгородэнерго | D2: Белгородские электрические сети | E2: 9155209202 | F2: 358205086910745 | G2: =IF(IFERROR(MATCH(F2,МДМ!$A:$A,0),0)=0,"Не установлено","Установлено") -> Установлено
A3: 2 | B3: Центр | C3: Белгородэнерго | D3: Белгородский | E3: 9155201469 | F3: 358205083587181 | G3: =IF(IFERROR(MATCH(F3,МДМ!$A:$A,0),0)=0,"Не установлено","Установлено") -> Установлено | H3: Егоров Владислав Владимирович | I3: 9102215242
A4: 3 | B4: Центр | C4: Белгородэнерго | D4: Борисовский | E4: 9107362214 | F4: 358205082874705 | G4: =IF(IFERROR(MATCH(F4,МДМ!$A:$A,0),0)=0,"Не установлено","Установлено") -> Установлено | H4: Шабров Роман Александрович | I4: 9803940075
A5: 4 | B5: Центр | C5: Белгородэнерго | D5: Валуйский | E5: 9155202154 | F5: 358205086906560 | G5: =IF(IFERROR(MATCH(F5,МДМ!$A:$A,0),0)=0,"Не установлено","Установлено") -> Установлено | H5: Лысенко Алексей Анатольевич | I5: 9102215254
A6: 5 | B6: Центр | C6: Белгородэнерго | D6: Яковлевский | E6: 9155203044 | F6: 358205086909002 | G6: =IF(IFERROR(MATCH(F6,МДМ!$A:$A,0),0)=0,"Не установлено","Установлено") -> Не установлено | H6: Агафонов Андрей Николаевич | I6: 9102215277
A7: 6 | B7: Центр | C7: Белгородэнерго | D7: Прохоровский | E7: 9803708255 | F7: 358205082874911 | G7: =IF(IFERROR(MATCH(F7,МДМ!$A:$A,0),0)=0,"Не установлено","Установлено") -> Установлено | H7: Козлов Юрий Анатольевич | I7: 9102215066
A8: 7 | B8: Центр | C8: Белгородэнерго | D8: Ракитянский | E8: 9155200551 | F8: 358205086913533 | G8: =IF(IFERROR(MATCH(F8,МДМ!$A:$A,0),0)=0,"Не установлено","Установлено") -> Установлено | H8: Федутенко Эдуард Викторович | I8: 9102215246
A9: 8 | B9: Центр | C9: Белгородэнерго | D9: Алексеевский | E9: 9155200553 | F9: 358205086913657 | G9: =IF(IFERROR(MATCH(F9,МДМ!$A:$A,0),0)=0,"Не установлено","Установлено") -> Установлено | H9: Рыжих Николай Михайлович | I9: 9192296984
A10: 9 | B10: Центр | C10: Белгородэнерго | D10: Губкинский | E10: 9803709156 | F10: 358205082874960 | G10: =IF(IFERROR(MATCH(F10,МДМ!$A:$A,0),0)=0,"Не установлено","Установлено") -> Установлено | H10: Чуриков Сергей Леонидович | I10: 9102215275
A11: 10 | B11: Центр | C11: Белгородэнерго | D11: Новооскольский | E11: 9155209179 | F11: 358205086909671 | G11: =IF(IFERROR(MATCH(F11,МДМ!$A:$A,0),0)=0,"Не установлено","Установлено") -> Не установлено | H11: Гамзатов Валерий Авалуевич | I11: 9192296052
A12: 11 | B12: Центр | C12: Белгородэнерго | D12: Ивнянский | E12: 9155200226 | F12: 358205086912220 | G12: =IF(IFERROR(MATCH(F12,МДМ!$A:$A,0),0)=0,"Не установлено","Установлено") -> Не установлено | H12: Бардокин Николай Александрович | I12: 9192296380
A13: 12 | B13: Центр | C13: Белгородэнерго | D13: Чернянский | E13: 9803708550 | F13: 358205083585870 | G13: =IF(IFERROR(MATCH(F13,МДМ!$A:$A,0),0)=0,"Не установлено","Установлено") -> Не установлено | H13: Банченко Сергей Михайлович | I13: 9155706670
A14: 13 | B14: Центр | C14: Белгородэнерго | D14: Красненский | E14: 9155200447 | F14: 358205086913061 | G14: =IF(IFERROR(MATCH(F14,МДМ!$A:$A,0),0)=0,"Не установлено","Установлено") -> Установлено | H14: Бабин Олег Иванович | I14: 9102215829
A15: 14 | B15: Центр | C15: Брянскэнерго | D15: Брянский | E15: 9206031225 | F15: 358205080871745 | G15: =IF(IFERROR(MATCH(F15,МДМ!$A:$A,0),0)=0,"Не установлено","Установлено") -> Не установлено | H15: Котов Евгений Олегович | I15: 9191913044
A16: 15 | B16: Центр | C16: Брянскэнерго | D16: Выгоничский | E16: 9206031976 | F16: 358205080845988 | G16: =IF(IFERROR(MATCH(F16,МДМ!$A:$A,0),0)=0,"Не установлено","Установлено") -> Не установлено | H16: Шматков Владимир Николаевич | I16: 9155356861
A17: 16 | B17: Центр | C17: Брянскэнерго | D17: Стародубский | E17: 9206032134 | F17: 358205080847315 | G17: =IF(IFERROR(MATCH(F17,МДМ!$A:$A,0),0)=0,"Не установлено","Установлено") -> Установлено | H17: Трусов Дмитрий Владимирович | I17: 9102301812
A18: 17 | B18: Центр | C18: Брянскэнерго | D18: Почепский | E18: 9206031245 | F18: 358205080898136 | G18: =IF(IFERROR(MATCH(F18,МДМ!$A:$A,0),0)=0,"Не установлено","Установлено") -> Установлено | H18: Вавулин Роман Алексеевич | I18: 9803021850
A19: 18 | B19: ЦИП | C19: Владимирэнерго | D19: Суздальский | E19: 9106700552 9106700553 9106700554 9106700558 | F19: 358205080890570 | G19: =IF(IFERROR(MATCH(F19,МДМ!$A:$A,0),0)=0,"Не установлено","Установлено") -> Установлено | H19: Волков Александр Сергеевич | I19: 9200556534
A20: 19 | B20: ЦИП | C20: Владимирэнерго | D20: Суздальский | E20: 9106700552 9106700553 9106700554 9106700558 | F20: 358205080890539 | G20: =IF(IFERROR(MATCH(F20,МДМ!$A:$A,0),0)=0,"Не установлено","Установлено") -> Не установлено | H20: Волков Александр Сергеевич | I20: 9200556534
A21: 20 | B21: ЦИП | C21: Владимирэнерго | D21: Суздальский | E21: 9106700552 9106700553 9106700554 9106700558 | F21: 358205080889770 | G21: =IF(IFERROR(MATCH(F21,МДМ!$A:$A,0),0)=0,"Не установлено","Установлено") -> Не установлено | H21: Волков Александр Сергеевич | I21: 9200556534
A22: 21 | B22: ЦИП | C22: Владимирэнерго | D22: Суздальский | E22: 9106700552 9106700553 9106700554 9106700558 | F22: 358205080890927 | G22: =IF(IFERROR(MATCH(F22,МДМ!$A:$A,0),0)=0,"Не установлено","Установлено") -> Не установлено | H22: Волков Александр Сергеевич | I22: 9200556534
A23: 22 | B23: ЦИП | C23: Владимирэнерго | D23: Судогодский | E23: 9106700443 9106700445 9106700449 | F23: 358205080900120 | G23: =IF(IFERROR(MATCH(F23,МДМ!$A:$A,0),0)=0,"Не установлено","Установлено") -> Не установлено | H23: Хрипачев Антон Николаевич | I23: 9100369328
A24: 23 | B24: ЦИП | C24: Владимирэнерго | D24: Судогодский | E24: 9106700443 9106700445 9106700449 | F24: 358205080890547 | G24: =IF(IFERROR(MATCH(F24,МДМ!$A:$A,0),0)=0,"Не установлено","Установлено") -> Не установлено | H24: Хрипачев Антон Николаевич | I24: 9100369328
A25: 24 | B25: ЦИП | C25: Владимирэнерго | D25: Судогодский | E25: 9106700443 9106700445 9106700449 | F25: 358205080890760 | G25: =IF(IFERROR(MATCH(F25,МДМ!$A:$A,0),0)=0,"Не установлено","Установлено") -> Не установлено | H25: Хрипачев Антон Николаевич | I25: 9100369328
A26: 25 | B26: ЦИП | C26: Владимирэнерго | D26: Александровский | E26: 9106700098 9106700112 9106700113 9190021136 9190021131 9101702541 | F26: 358205080903639 | G26: =IF(IFERROR(MATCH(F26,МДМ!$A:$A,0),0)=0,"Не установлено","Установлено") -> Не установлено | H26: Чуев Андрей Николаевич | I26: 9100362352
A27: 26 | B27: ЦИП | C27: Владимирэнерго | D27: Александровский | E27: 9106700098 9106700112 9106700113 9190021136 9190021131 9101702541 | F27: 358205080903670 | G27: =IF(IFERROR(MATCH(F27,МДМ!$A:$A,0),0)=0,"Не установлено","Установлено") -> Установлено | H27: Чуев Андрей Николаевич | I27: 9100362352
A28: 27 | B28: ЦИП | C28: Владимирэнерго | D28: Александровский | E28: 9106700098 9106700112 9106700113 9190021136 9190021131 9101702541 | F28: 358205080903696 | G28: =IF(IFERROR(MATCH(F28,МДМ!$A:$A,0),0)=0,"Не установлено","Установлено") -> Установлено | H28: Чуев Андрей Николаевич | I28: 9100362352
A29: 28 | B29: ЦИП | C29: Владимирэнерго | D29: Александровский | E29: 9106700098 9106700112 9106700113 9190021136 9190021131 9101702541 | F29: 358205083574502 | G29: =IF(IFERROR(MATCH(F29,МДМ!$A:$A,0),0)=0,"Не установлено","Установлено") -> Установлено | H29: Чуев Андрей Николаевич | I29: 9100362352
A30: 29 | B30: ЦИП | C30: Владимирэнерго | D30: Александровский | E30: 9106700098 9106700112 9106700113 9190021136 9190021131 9101702541 | F30: 358205086913806 | G30: =IF(IFERROR(MATCH(F30,МДМ!$A:$A,0),0)=0,"Не установлено","Установлено") -> Установлено | H30: Чуев Андрей Николаевич | I30: 9100362352
... A33: 32 | B33: ЦИП | C33: Владимирэнерго | D33: Киржачский | E33: 9106700092 9157600294 | F33: 358205083574577 | G33: =IF(IFERROR(MATCH(F33,МДМ!$A:$A,0),0)=0,"Не установлено","Установлено") -> Не установлено | H33: Ботков Антон Алексеевич | I33: 9106765272
A34: 33 | B34: ЦИП | C34: Владимирэнерго | D34: Гороховецкий | E34: 9106700668 9106700771 9106700772 | F34: 358205080889887 | G34: =IF(IFERROR(MATCH(F34,МДМ!$A:$A,0),0)=0,"Не установлено","Установлено") -> Установлено | H34: Мишин Сергей Александрович | I34: Sergey_Aleksandrovich_Mishin@mail.local
A35: 34 | B35: ЦИП | C35: Владимирэнерго | D35: Гороховецкий | E35: 9106700668 9106700771 9106700772 | F35: 358205080889838 | G35: =IF(IFERROR(MATCH(F35,МДМ!$A:$A,0),0)=0,"Не установлено","Установлено") -> Не установлено | H35: Мишин Сергей Александрович | I35: Sergey_Aleksandrovich_Mishin@mail.local
A36: 35 | B36: ЦИП | C36: Владимирэнерго | D36: Гороховецкий | E36: 9106700668 9106700771 9106700772 | F36: 358205080890067 | G36: =IF(IFERROR(MATCH(F36,МДМ!$A:$A,0),0)=0,"Не установлено","Установлено") -> Не установлено | H36: Мишин Сергей Александрович | I36: Sergey_Aleksandrovich_Mishin@mail.local
A37: 36 | B37: ЦИП | C37: Владимирэнерго | D37: Камешковский | E37: 9106700119 9106700217 9106700224 | F37: 358205080890661 | G37: =IF(IFERROR(MATCH(F37,МДМ!$A:$A,0),0)=0,"Не установлено","Установлено") -> Установлено | H37: Ломакин Николай Иванович | I37: 9106765924
A38: 37 | B38: ЦИП | C38: Владимирэнерго | D38: Камешковский | E38: 9106700119 9106700217 9106700224 | F38: 358205080890554 | G38: =IF(IFERROR(MATCH(F38,МДМ!$A:$A,0),0)=0,"Не установлено","Установлено") -> Установлено | H38: Ломакин Николай Иванович | I38: 9106765924
A39: 38 | B39: ЦИП | C39: Владимирэнерго | D39: Камешковский | E39: 9106700119 9106700217 9106700224 | F39: 358205080890620 | G39: =IF(IFERROR(MATCH(F39,МДМ!$A:$A,0),0)=0,"Не установлено","Установлено") -> Установлено | H39: Ломакин Николай Иванович | I39: 9106765924
A40: 39 | B40: ЦИП | C40: Владимирэнерго | D40: Петушинский | E40: 9106700225 9106700441 | F40: 358205080890885 | G40: =IF(IFERROR(MATCH(F40,МДМ!$A:$A,0),0)=0,"Не установлено","Установлено") -> Не установлено | H40: Шубин Алексей Анатольевич | I40: Aleksey_Anatol'evich_Shubin@mail.local
A41: 40 | B41: ЦИП | C41: Владимирэнерго | D41: Петушинский | E41: 9106700225 9106700441 | F41: 358205080900106 | G41: =IF(IFERROR(MATCH(F41,МДМ!$A:$A,0),0)=0,"Не установлено","Установлено") -> Не установлено | H41: Шубин Алексей Анатольевич | I41: Aleksey_Anatol'evich_Shubin@mail.local
A42: 41 | B42: ЦИП | C42: Владимирэнерго | D42: Юрьев-Польский | E42: 9106700114 9106700115 9106700118 | F42: 358205080900049 | G42: =IF(IFERROR(MATCH(F42,МДМ!$A:$A,0),0)=0,"Не установлено","Установлено") -> Не установлено | H42: Савельев Василий Алексеевич | I42: 9106765300
...

Sheet Неплан ОПЭ
A1: IMEI | B1: Дата активности | C1: Филиал
A2: 358205084170847 | B2: 45335.332 | C2: Тулэнерго
A3: 358205083587272 | B3: 45336.212 | C3: Костромаэнерго
A4: 358205083588205 | B4: 45336.225 | C4: Липецкэнерго
A5: 358205084539561 | B5: 45338.495 | C5: Белгородэнерго
A6: 358205086912733 | B6: 45335.714 | C6: Белгородэнерго
A7: 358205080899183 | B7: 45335.36 | C7: Воронежэнерго
A8: 358205080900163 | B8: 45337.409 | C8: Воронежэнерго
A9: 358205080890471 | B9: 45335.261 | C9: Удмуртэнерго
A10: 358205080902987 | B10: 45335.469 | C10: Рязаньэнерго
A11: 358205080904546 | B11: 45335.468 | C11: НижНовЭнерго
A12: 358205083587207 | B12: 45336.219 | C12: Тулэнерго
A13: 358205080890364 | B13: 45338.5 | C13: НижНовЭнерго
... A691: 358205080899779 | B691: 45337.408 | C691: Воронежэнерго

Sheet МДМ
A1: IMEI | B1: Дата активности | C1: Филиал | D1: APN
A2: 358205084170847 | B2: 45335.332 | C2: Тулэнерго | D2: =INDEX('План ОПЭ'!$D$2:$D$195,MATCH(_1[[#This Row],[IMEI]],'План ОПЭ'!$F$2:$F$195,0),1) -> #N/A
A3: 358205083587272 | B3: 45336.212 | C3: Костромаэнерго | D3: =#NAME? -> #NAME?
A4: 358205083588205 | B4: 45336.225 | C4: Липецкэнерго | D4: =#NAME? -> #NAME?
A5: 358205084520801 | B5: 45335.432 | C5: Тамбовэнерго | D5: =#NAME? -> #NAME?
A6: 358205084539561 | B6: 45338.495 | C6: Белгородэнерго | D6: =#NAME? -> #NAME?
A7: 358205086912733 | B7: 45335.714 | C7: Белгородэнерго | D7: =#NAME? -> #NAME?
A8: 358205080899183 | B8: 45335.36 | C8: Воронежэнерго | D8: =#NAME? -> #NAME?
A9: 358205080900163 | B9: 45337.409 | C9: Воронежэнерго | D9: =#NAME? -> #NAME?
A10: 358205080890471 | B10: 45335.261 | C10: Удмуртэнерго | D10: =#NAME? -> #NAME?
A11: 358205080890554 | B11: 45335.464 | C11: Владимирэнерго | D11: =#NAME? -> #NAME?
A12: 358205080890620 | B12: 45335.43 | C12: Владимирэнерго | D12: =#NAME? -> #NAME?
A13: 358205080890661 | B13: 45335.462 | C13: Владимирэнерго | D13: =#NAME? -> #NAME?
A14: 358205080899597 | B14: 45335.643 | C14: Владимирэнерго | D14: =#NAME? -> #NAME?
... A790: 358205080899779 | B790: 45337.408 | C790: Воронежэнерго | D790: =#NAME? -> #NAME?
